Workbook

Sheet 2026
A1: Hvor | B1: Dato | C1: Ukedag | D1: Time | E1: Timesats | F1: Fakturert | G1: Kommentar | H1: SUM | K1: Faktura sendt | L1: Utbetalt
A2: Aker S | B2: 46027 | C2: =TEXT(B2,"dddd") -> mandag | D2: 1 | E2: =VLOOKUP(A2,formler!$G$3:$H$5,2,FALSE) -> 1000 | F2: =D2*E2 -> 1000
A3: Equinor ML33 | B3: 46028 | C3: =TEXT(B3,"dddd") -> tirsdag | D3: 1.5 | E3: =VLOOKUP(A3,formler!$G$3:$H$5,2,FALSE) -> 773 | F3: =D3*E3 -> 1159.5
A4: Telenor | B4: 46030 | C4: =TEXT(B4,"dddd") -> torsdag | D4: 1 | E4: =VLOOKUP(A4,formler!$G$3:$H$5,2,FALSE) -> 1000 | F4: =D4*E4 -> 1000
A5: Equinor ML33 | B5: 46030 | C5: =TEXT(B5,"dddd") -> torsdag | D5: 1 | E5: =VLOOKUP(A5,formler!$G$3:$H$5,2,FALSE) -> 773 | F5: =D5*E5 -> 773
A6: Aker S | B6: 46034 | C6: =TEXT(B6,"dddd") -> mandag | D6: 1 | E6: =VLOOKUP(A6,formler!$G$3:$H$5,2,FALSE) -> 1000 | F6: =D6*E6 -> 1000
A7: Equinor ML33 | B7: 46035 | C7: =TEXT(B7,"dddd") -> tirsdag | D7: 1.5 | E7: =VLOOKUP(A7,formler!$G$3:$H$5,2,FALSE) -> 773 | F7: =D7*E7 -> 1159.5
A8: Telenor | B8: 46037 | C8: =TEXT(B8,"dddd") -> torsdag | D8: 1 | E8: =VLOOKUP(A8,formler!$G$3:$H$5,2,FALSE) -> 1000 | F8: =D8*E8 -> 1000
A9: Equinor ML33 | B9: 46037 | C9: =TEXT(B9,"dddd") -> torsdag | D9: 1 | E9: =VLOOKUP(A9,formler!$G$3:$H$5,2,FALSE) -> 773 | F9: =D9*E9 -> 773
A10: Aker S | B10: 46041 | C10: =TEXT(B10,"dddd") -> mandag | D10: 1 | E10: =VLOOKUP(A10,formler!$G$3:$H$5,2,FALSE) -> 1000 | F10: =D10*E10 -> 1000
A11: Equinor ML33 | B11: 46042 | C11: =TEXT(B11,"dddd") -> tirsdag | D11: 2.5 | E11: =VLOOKUP(A11,formler!$G$3:$H$5,2,FALSE) -> 773 | F11: =D11*E11 -> 1932.5
A12: Telenor | B12: 46044 | C12: =TEXT(B12,"dddd") -> torsdag | D12: 1 | E12: =VLOOKUP(A12,formler!$G$3:$H$5,2,FALSE) -> 1000 | F12: =D12*E12 -> 1000
A13: Equinor ML33 | B13: 46044 | C13: =TEXT(B13,"dddd") -> torsdag | D13: 1 | E13: =VLOOKUP(A13,formler!$G$3:$H$5,2,FALSE) -> 773 | F13: =D13*E13 -> 773
A14: Aker S | B14: 46048 | C14: =TEXT(B14,"dddd") -> mandag | D14: 1 | E14: =VLOOKUP(A14,formler!$G$3:$H$5,2,FALSE) -> 1000 | F14: =D14*E14 -> 1000
A15: Equinor ML33 | B15: 46049 | C15: =TEXT(B15,"dddd") -> tirsdag | D15: 1.5 | E15: =VLOOKUP(A15,formler!$G$3:$H$5,2,FALSE) -> 773 | F15: =D15*E15 -> 1159.5 | I15: Aker S | J15: =SUMIF(A2:F17,I15,F2:F17) -> 4000 | K15: februar | L15: 46059
A16: Telenor | B16: 46051 | C16: =TEXT(B16,"dddd") -> torsdag | D16: 1 | E16: =VLOOKUP(A16,formler!$G$3:$H$5,2,FALSE) -> 1000 | F16: =D16*E16 -> 1000 | I16: Equinor ML33 | J16: =SUMIF(A2:F17,I16,F2:F17) -> 8503 | K16: 46043 | L16: 46044
A17: Equinor ML33 | B17: 46051 | C17: =TEXT(B17,"dddd") -> torsdag | D17: 1 | E17: =VLOOKUP(A17,formler!$G$3:$H$5,2,FALSE) -> 773 | F17: =D17*E17 -> 773 | H17: =SUM(F2:F17) -> 16503 | I17: Telenor | J17: =SUMIF(A2:F17,I17,F2:F17) -> 4000 | K17: 46051 | L17: 46071
A18: Aker S | B18: 46055 | C18: =TEXT(B18,"dddd") -> mandag | D18: 0 | E18: =VLOOKUP(A18,formler!$G$3:$H$5,2,FALSE) -> 1000 | F18: =D18*E18 -> 0 | G18: Alpene | H18: Vikar
A19: Equinor ML33 | B19: 46056 | C19: =TEXT(B19,"dddd") -> tirsdag | D19: 0 | E19: =VLOOKUP(A19,formler!$G$3:$H$5,2,FALSE) -> 773 | F19: =D19*E19 -> 0 | G19: Alpene | H19: Vikar
A20: Telenor | B20: 46058 | C20: =TEXT(B20,"dddd") -> torsdag | D20: 0 | E20: =VLOOKUP(A20,formler!$G$3:$H$5,2,FALSE) -> 1000 | F20: =D20*E20 -> 0 | G20: Alpene | H20: Vikar
A21: Equinor ML33 | B21: 46058 | C21: =TEXT(B21,"dddd") -> torsdag | D21: 0 | E21: =VLOOKUP(A21,formler!$G$3:$H$5,2,FALSE) -> 773 | F21: =D21*E21 -> 0 | G21: Alpene | H21: Vikar
A22: Aker S | B22: 46062 | C22: =TEXT(B22,"dddd") -> mandag | D22: 0 | E22: =VLOOKUP(A22,formler!$G$3:$H$5,2,FALSE) -> 1000 | F22: =D22*E22 -> 0 | G22: Alpene | H22: Vikar
A23: Equinor ML33 | B23: 46063 | C23: =TEXT(B23,"dddd") -> tirsdag | D23: 0 | E23: =VLOOKUP(A23,formler!$G$3:$H$5,2,FALSE) -> 773 | F23: =D23*E23 -> 0 | G23: Alpene | H23: Vikar
A24: Telenor | B24: 46065 | C24: =TEXT(B24,"dddd") -> torsdag | D24: 1 | E24: =VLOOKUP(A24,formler!$G$3:$H$5,2,FALSE) -> 1000 | F24: =D24*E24 -> 1000
A25: Equinor ML33 | B25: 46065 | C25: =TEXT(B25,"dddd") -> torsdag | D25: 1 | E25: =VLOOKUP(A25,formler!$G$3:$H$5,2,FALSE) -> 773 | F25: =D25*E25 -> 773
A26: Aker S | B26: 46069 | C26: =TEXT(B26,"dddd") -> mandag | D26: 1 | E26: =VLOOKUP(A26,formler!$G$3:$H$5,2,FALSE) -> 1000 | F26: =D26*E26 -> 1000
A27: Equinor ML33 | B27: 46070 | C27: =TEXT(B27,"dddd") -> tirsdag | D27: 2.5 | E27: =VLOOKUP(A27,formler!$G$3:$H$5,2,FALSE) -> 773 | F27: =D27*E27 -> 1932.5
A28: Telenor | B28: 46072 | C28: =TEXT(B28,"dddd") -> torsdag | D28: 1 | E28: =VLOOKUP(A28,formler!$G$3:$H$5,2,FALSE) -> 1000 | F28: =D28*E28 -> 1000
A29: Equinor ML33 | B29: 46072 | C29: =TEXT(B29,"dddd") -> torsdag | D29: 1 | E29: =VLOOKUP(A29,formler!$G$3:$H$5,2,FALSE) -> 773 | F29: =D29*E29 -> 773
A30: Aker S | B30: 46076 | C30: =TEXT(B30,"dddd") -> mandag | D30: 1 | E30: =VLOOKUP(A30,formler!$G$3:$H$5,2,FALSE) -> 1000 | F30: =D30*E30 -> 1000
A31: Equinor ML33 | B31: 46077 | C31: =TEXT(B31,"dddd") -> tirsdag | D31: 1.5 | E31: =VLOOKUP(A31,formler!$G$3:$H$5,2,FALSE) -> 773 | F31: =D31*E31 -> 1159.5 | I31: Aker S | J31: =SUMIF(A18:F33,I31,F18:F33) -> 2000 | K31: 46073 | L31: 45694
A32: Telenor | B32: 46079 | C32: =TEXT(B32,"dddd") -> torsdag | D32: 1 | E32: =VLOOKUP(A32,formler!$G$3:$H$5,2,FALSE) -> 1000 | F32: =D32*E32 -> 1000 | I32: Equinor ML33 | J32: =SUMIF(A18:F33,I32,F18:F33) -> 5411 | K32: 46073 | L32: 46076
A33: Equinor ML33 | B33: 46079 | C33: =TEXT(B33,"dddd") -> torsdag | D33: 1 | E33: =VLOOKUP(A33,formler!$G$3:$H$5,2,FALSE) -> 773 | F33: =D33*E33 -> 773 | H33: =SUM(F18:F33) -> 10411 | I33: Telenor | J33: =SUMIF(A18:F33,I33,F18:F33) -> 3000 | K33: 46079 | L33: 46066
A34: Aker S | B34: 46083 | C34: =TEXT(B34,"dddd") -> mandag | D34: 1 | E34: =VLOOKUP(A34,formler!$G$3:$H$5,2,FALSE) -> 1000 | F34: =D34*E34 -> 1000
A35: Equinor ML33 | B35: 46084 | C35: =TEXT(B35,"dddd") -> tirsdag | D35: 1.5 | E35: =VLOOKUP(A35,formler!$G$3:$H$5,2,FALSE) -> 773 | F35: =D35*E35 -> 1159.5
A36: Telenor | B36: 46086 | C36: =TEXT(B36,"dddd") -> torsdag | D36: 1 | E36: =VLOOKUP(A36,formler!$G$3:$H$5,2,FALSE) -> 1000 | F36: =D36*E36 -> 1000
A37: Equinor ML33 | B37: 46086 | C37: =TEXT(B37,"dddd") -> torsdag | D37: 1 | E37: =VLOOKUP(A37,formler!$G$3:$H$5,2,FALSE) -> 773 | F37: =D37*E37 -> 773
A38: Aker S | B38: 46090 | C38: =TEXT(B38,"dddd") -> mandag | D38: 1 | E38: =VLOOKUP(A38,formler!$G$3:$H$5,2,FALSE) -> 1000 | F38: =D38*E38 -> 1000
A39: Equinor ML33 | B39: 46091 | C39: =TEXT(B39,"dddd") -> tirsdag | D39: 2.5 | E39: =VLOOKUP(A39,formler!$G$3:$H$5,2,FALSE) -> 773 | F39: =D39*E39 -> 1932.5
A40: Telenor | B40: 46093 | C40: =TEXT(B40,"dddd") -> torsdag | D40: 1 | E40: =VLOOKUP(A40,formler!$G$3:$H$5,2,FALSE) -> 1000 | F40: =D40*E40 -> 1000
...

Sheet 2025
A1: Dato | B1: Ukedag | C1: Time | D1: Timesats | E1: Fakturert | F1: Kommentar | G1: SUM | I1: Faktura sendt | J1: Utbetalt
A2: 45664 | B2: =VLOOKUP(formler!D3,formler!$A$2:$B$8,2,FALSE) -> Tirsdag | C2: 1.5 | D2: 750 | E2: =C2*D2 -> 1125
A3: 45666 | B3: =VLOOKUP(formler!D4,formler!$A$2:$B$8,2,FALSE) -> Torsdag | C3: 1 | D3: 750 | E3: =C3*D3 -> 750
A4: 45671 | B4: =VLOOKUP(formler!D5,formler!$A$2:$B$8,2,FALSE) -> Tirsdag | C4: 1.5 | D4: 750 | E4: =C4*D4 -> 1125
A5: 45673 | B5: =VLOOKUP(formler!D6,formler!$A$2:$B$8,2,FALSE) -> Torsdag | C5: 1 | D5: 750 | E5: =C5*D5 -> 750
A6: 45678 | B6: =VLOOKUP(formler!D7,formler!$A$2:$B$8,2,FALSE) -> Tirsdag | C6: 2.5 | D6: 750 | E6: =C6*D6 -> 1875
A7: 45680 | B7: =VLOOKUP(formler!D8,formler!$A$2:$B$8,2,FALSE) -> Torsdag | C7: 1 | D7: 750 | E7: =C7*D7 -> 750 | M7: =SUM(E2,E4,E8) -> 3375
A8: 45685 | B8: =VLOOKUP(formler!D9,formler!$A$2:$B$8,2,FALSE) -> Tirsdag | C8: 1.5 | D8: 750 | E8: =C8*D8 -> 1125
A9: 45687 | B9: =VLOOKUP(formler!D10,formler!$A$2:$B$8,2,FALSE) -> Torsdag | C9: 1 | D9: 750 | E9: =C9*D9 -> 750 | G9: =SUM(E2:E9) -> 8250
A10: 45692 | B10: Tirsdag | C10: 2.5 | D10: 750 | E10: =C10*D10 -> 1875
A11: 45694 | B11: =VLOOKUP(formler!D12,formler!$A$2:$B$8,2,FALSE) -> Torsdag | C11: 1 | D11: 750 | E11: =C11*D11 -> 750
A12: 45699 | B12: =VLOOKUP(formler!D13,formler!$A$2:$B$8,2,FALSE) -> Tirsdag | C12: 0 | D12: 750 | E12: =C12*D12 -> 0 | F12: Alpene | G12: Vikar
A13: 45701 | B13: =VLOOKUP(formler!D14,formler!$A$2:$B$8,2,FALSE) -> Torsdag | C13: 1 | D13: 750 | E13: =C13*D13 -> 750
A14: 45706 | B14: =VLOOKUP(formler!D15,formler!$A$2:$B$8,2,FALSE) -> Tirsdag | C14: 1.5 | D14: 750 | E14: =C14*D14 -> 1125
A15: 45708 | B15: =VLOOKUP(formler!D16,formler!$A$2:$B$8,2,FALSE) -> Torsdag | C15: 1 | D15: 750 | E15: =C15*D15 -> 750
A16: 45713 | B16: =VLOOKUP(formler!D17,formler!$A$2:$B$8,2,FALSE) -> Tirsdag | C16: 2.5 | D16: 750 | E16: =C16*D16 -> 1875
A17: 45715 | B17: =VLOOKUP(formler!D18,formler!$A$2:$B$8,2,FALSE) -> Torsdag | C17: 1 | D17: 750 | E17: =C17*D17 -> 750 | G17: =SUM(E10:E17) -> 7875 | P17: =3000+1875+3375 -> 8250
A18: 45720 | B18: =VLOOKUP(formler!D19,formler!$A$2:$B$8,2,FALSE) -> Tirsdag | C18: 1.5 | D18: 750 | E18: =C18*D18 -> 1125
A19: 45722 | B19: =VLOOKUP(formler!D20,formler!$A$2:$B$8,2,FALSE) -> Torsdag | C19: 1 | D19: 750 | E19: =C19*D19 -> 750 | L19: 3000
A20: 45727 | B20: =VLOOKUP(formler!D21,formler!$A$2:$B$8,2,FALSE) -> Tirsdag | C20: 1.5 | D20: 750 | E20: =C20*D20 -> 1125 | L20: 3375
A21: 45729 | B21: =VLOOKUP(formler!D22,formler!$A$2:$B$8,2,FALSE) -> Torsdag | C21: 1 | D21: 750 | E21: =C21*D21 -> 750 | L21: 1875
A22: 45734 | B22: =VLOOKUP(formler!D23,formler!$A$2:$B$8,2,FALSE) -> Tirsdag | C22: 2.5 | D22: 750 | E22: =C22*D22 -> 1875
A23: 45736 | B23: =VLOOKUP(formler!D24,formler!$A$2:$B$8,2,FALSE) -> Torsdag | C23: 1 | D23: 750 | E23: =C23*D23 -> 750
A24: 45741 | B24: =VLOOKUP(formler!D25,formler!$A$2:$B$8,2,FALSE) -> Tirsdag | C24: 1.5 | D24: 750 | E24: =C24*D24 -> 1125
A25: 45743 | B25: =VLOOKUP(formler!D26,formler!$A$2:$B$8,2,FALSE) -> Torsdag | C25: 1 | D25: 750 | E25: =C25*D25 -> 750 | G25: =SUM(E18:E25) -> 8250
A26: 45748 | B26: =VLOOKUP(formler!D27,formler!$A$2:$B$8,2,FALSE) -> Tirsdag | C26: 1.5 | D26: 750 | E26: =C26*D26 -> 1125
A27: 45750 | B27: =VLOOKUP(formler!D28,formler!$A$2:$B$8,2,FALSE) -> Torsdag | C27: 1 | D27: 750 | E27: =C27*D27 -> 750
A28: 45755 | B28: =VLOOKUP(formler!D29,formler!$A$2:$B$8,2,FALSE) -> Tirsdag | C28: 2.5 | D28: 750 | E28: =C28*D28 -> 1875
A29: 45757 | B29: =VLOOKUP(formler!D30,formler!$A$2:$B$8,2,FALSE) -> Torsdag | C29: 1 | D29: 750 | E29: =C29*D29 -> 750
A30: 45762 | B30: =VLOOKUP(formler!D31,formler!$A$2:$B$8,2,FALSE) -> Tirsdag | C30: 0 | D30: 750 | E30: =C30*D30 -> 0 | F30: Påske
A31: 45764 | B31: =VLOOKUP(formler!D32,formler!$A$2:$B$8,2,FALSE) -> Torsdag | C31: 0 | D31: 750 | E31: =C31*D31 -> 0 | F31: Påske
A32: 45769 | B32: =VLOOKUP(formler!D33,formler!$A$2:$B$8,2,FALSE) -> Tirsdag | C32: 1.5 | D32: 750 | E32: =C32*D32 -> 1125
A33: 45771 | B33: =VLOOKUP(formler!D34,formler!$A$2:$B$8,2,FALSE) -> Torsdag | C33: 1 | D33: 750 | E33: =C33*D33 -> 750
A34: 45776 | B34: =VLOOKUP(formler!D35,formler!$A$2:$B$8,2,FALSE) -> Tirsdag | C34: 2.5 | D34: 750 | E34: =C34*D34 -> 1875 | G34: =SUM(E26:E34) -> 8250
A35: 45778 | B35: =VLOOKUP(formler!D36,formler!$A$2:$B$8,2,FALSE) -> Torsdag | C35: 0 | D35: 750 | E35: =C35*D35 -> 0 | F35: 45413
A36: 45783 | B36: =VLOOKUP(formler!D37,formler!$A$2:$B$8,2,FALSE) -> Tirsdag | C36: 1.5 | D36: 750 | E36: =C36*D36 -> 1125
A37: 45785 | B37: =VLOOKUP(formler!D38,formler!$A$2:$B$8,2,FALSE) -> Torsdag | C37: 1 | D37: 750 | E37: =C37*D37 -> 750
A38: 45790 | B38: =VLOOKUP(formler!D39,formler!$A$2:$B$8,2,FALSE) -> Tirsdag | C38: 1.5 | D38: 750 | E38: =C38*D38 -> 1125
A39: 45792 | B39: =VLOOKUP(formler!D40,formler!$A$2:$B$8,2,FALSE) -> Torsdag | C39: 1 | D39: 750 | E39: =C39*D39 -> 750
A40: 45797 | B40: =VLOOKUP(formler!D41,formler!$A$2:$B$8,2,FALSE) -> Tirsdag | C40: 2.5 | D40: 750 | E40: =C40*D40 -> 1875
...

Sheet formler
D1: Dag
A2: 1 | B2: Mandag | D2: 1 | G2: Timespris
A3: 2 | B3: Tirsdag | D3: =WEEKDAY('2025'!A2,2) -> 2 | G3: Aker S | H3: 1000
A4: 3 | B4: Onsdag | D4: =WEEKDAY('2025'!A3,2) -> 4 | G4: Equinor ML33 | H4: 773
A5: 4 | B5: Torsdag | D5: =WEEKDAY('2025'!A4,2) -> 2 | G5: Telenor | H5: 1000
A6: 5 | B6: Fredag | D6: =WEEKDAY('2025'!A5,2) -> 4
A7: 6 | B7: Lørdag | D7: =WEEKDAY('2025'!A6,2) -> 2
A8: 7 | B8: Søndag | D8: =WEEKDAY('2025'!A7,2) -> 4
D9: =WEEKDAY('2025'!A8,2) -> 2
D10: =WEEKDAY('2025'!A9,2) -> 4
D11: =WEEKDAY('2025'!A10,2) -> 2
D12: =WEEKDAY('2025'!A11,2) -> 4
D13: =WEEKDAY('2025'!A12,2) -> 2
D14: =WEEKDAY('2025'!A13,2) -> 4
D15: =WEEKDAY('2025'!A14,2) -> 2
D16: =WEEKDAY('2025'!A15,2) -> 4
D17: =WEEKDAY('2025'!A16,2) -> 2
D18: =WEEKDAY('2025'!A17,2) -> 4
D19: =WEEKDAY('2025'!A18,2) -> 2
D20: =WEEKDAY('2025'!A19,2) -> 4
... D52: =WEEKDAY('2025'!A51,2) -> 4
D53: =WEEKDAY('2025'!A56,2) -> 2
D54: =WEEKDAY('2025'!A57,2) -> 4
D55: =WEEKDAY('2025'!A58,2) -> 2
D56: =WEEKDAY('2025'!A59,2) -> 4
D57: =WEEKDAY('2025'!A60,2) -> 2
D58: =WEEKDAY('2025'!A61,2) -> 4
D59: =WEEKDAY('2025'!A62,2) -> 2
D60: =WEEKDAY('2025'!A63,2) -> 4
D61: =WEEKDAY('2025'!A64,2) -> 2
D62: =WEEKDAY('2025'!A65,2) -> 4
D63: =WEEKDAY('2025'!A66,2) -> 2
D64: =WEEKDAY('2025'!A67,2) -> 4
... D102: =WEEKDAY('2025'!A105,2) -> 6

Sheet Ola
A1: Dato | B1: Ukedag | C1: Time | F1: Korrigert versjon
A2: 45664 | B2: =VLOOKUP(formler!D3,formler!$A$2:$B$8,2,FALSE) -> Tirsdag | C2: 1.5 | F2: 45664 | G2: Tirsdag | H2: 1.5
A3: 45666 | B3: =VLOOKUP(formler!D4,formler!$A$2:$B$8,2,FALSE) -> Torsdag | C3: 1 | F3: 45666 | G3: Torsdag | H3: 1
A4: 45671 | B4: =VLOOKUP(formler!D5,formler!$A$2:$B$8,2,FALSE) -> Tirsdag | C4: 1.5 | F4: 45671 | G4: Tirsdag | H4: 1.5
A5: 45673 | B5: =VLOOKUP(formler!D6,formler!$A$2:$B$8,2,FALSE) -> Torsdag | C5: 1 | F5: 45673 | G5: Torsdag | H5: 1
A6: 45678 | B6: =VLOOKUP(formler!D7,formler!$A$2:$B$8,2,FALSE) -> Tirsdag | C6: 2.5 | F6: 45678 | G6: Tirsdag | H6: 2.5
A7: 45680 | B7: =VLOOKUP(formler!D8,formler!$A$2:$B$8,2,FALSE) -> Torsdag | C7: 1 | F7: 45680 | G7: Torsdag | H7: 1
A8: 45685 | B8: =VLOOKUP(formler!D9,formler!$A$2:$B$8,2,FALSE) -> Tirsdag | C8: 1.5 | F8: 45685 | G8: Tirsdag | H8: 1.5
A9: 45687 | B9: =VLOOKUP(formler!D10,formler!$A$2:$B$8,2,FALSE) -> Torsdag | C9: 1 | F9: 45687 | G9: Torsdag | H9: 1
A10: 45692 | B10: Tirsdag | C10: 1.5 | F10: 45692 | G10: Tirsdag | H10: 2.5
A11: 45694 | B11: =VLOOKUP(formler!D12,formler!$A$2:$B$8,2,FALSE) -> Torsdag | C11: 1 | F11: 45694 | G11: Torsdag | H11: 1
A12: 45699 | B12: =VLOOKUP(formler!D13,formler!$A$2:$B$8,2,FALSE) -> Tirsdag | C12: 2.5 | D12: mulig ferie | F12: 45699 | G12: Tirsdag | H12: 0 | I12: Ferie
A13: 45701 | B13: =VLOOKUP(formler!D14,formler!$A$2:$B$8,2,FALSE) -> Torsdag | C13: 1 | F13: 45701 | G13: Torsdag | H13: 1
A14: 45706 | B14: =VLOOKUP(formler!D15,formler!$A$2:$B$8,2,FALSE) -> Tirsdag | C14: 1.5 | F14: 45706 | G14: Tirsdag | H14: 1.5
A15: 45708 | B15: =VLOOKUP(formler!D16,formler!$A$2:$B$8,2,FALSE) -> Torsdag | C15: 1 | F15: 45708 | G15: Torsdag | H15: 1
A16: 45713 | B16: =VLOOKUP(formler!D17,formler!$A$2:$B$8,2,FALSE) -> Tirsdag | C16: 1.5 | F16: 45713 | G16: Tirsdag | H16: 2.5
A17: 45715 | B17: =VLOOKUP(formler!D18,formler!$A$2:$B$8,2,FALSE) -> Torsdag | C17: 1 | F17: 45715 | G17: Torsdag | H17: 1
A18: 45720 | B18: =VLOOKUP(formler!D19,formler!$A$2:$B$8,2,FALSE) -> Tirsdag | C18: 2.5 | F18: 45720 | G18: Tirsdag | H18: 1.5
A19: 45722 | B19: =VLOOKUP(formler!D20,formler!$A$2:$B$8,2,FALSE) -> Torsdag | C19: 1 | F19: 45722 | G19: Torsdag | H19: 1
A20: 45727 | B20: =VLOOKUP(formler!D21,formler!$A$2:$B$8,2,FALSE) -> Tirsdag | C20: 1.5 | F20: 45727 | G20: Tirsdag | H20: 1.5
A21: 45729 | B21: =VLOOKUP(formler!D22,formler!$A$2:$B$8,2,FALSE) -> Torsdag | C21: 1 | F21: 45729 | G21: Torsdag | H21: 1
A22: 45734 | B22: =VLOOKUP(formler!D23,formler!$A$2:$B$8,2,FALSE) -> Tirsdag | C22: 1.5 | F22: 45734 | G22: Tirsdag | H22: 2.5
A23: 45736 | B23: =VLOOKUP(formler!D24,formler!$A$2:$B$8,2,FALSE) -> Torsdag | C23: 1 | F23: 45736 | G23: Torsdag | H23: 1
A24: 45741 | B24: =VLOOKUP(formler!D25,formler!$A$2:$B$8,2,FALSE) -> Tirsdag | C24: 2.5 | F24: 45741 | G24: Tirsdag | H24: 1.5
... A29: 45757 | B29: =VLOOKUP(formler!D30,formler!$A$2:$B$8,2,FALSE) -> Torsdag | C29: 1 | F29: 45757 | G29: Torsdag | H29: 1
A30: 45762 | B30: =VLOOKUP(formler!D31,formler!$A$2:$B$8,2,FALSE) -> Tirsdag | C30: 0 | D30: Påske | F30: 45762 | G30: Tirsdag | H30: 0 | I30: Påske
A31: 45764 | B31: =VLOOKUP(formler!D32,formler!$A$2:$B$8,2,FALSE) -> Torsdag | C31: 0 | D31: Påske | F31: 45764 | G31: Torsdag | H31: 0 | I31: Påske
A32: 45769 | B32: =VLOOKUP(formler!D33,formler!$A$2:$B$8,2,FALSE) -> Tirsdag | C32: 1.5 | F32: 45769 | G32: Tirsdag | H32: 1.5
A33: 45771 | B33: =VLOOKUP(formler!D34,formler!$A$2:$B$8,2,FALSE) -> Torsdag | C33: 1 | F33: 45771 | G33: Torsdag | H33: 1
A34: 45776 | B34: =VLOOKUP(formler!D35,formler!$A$2:$B$8,2,FALSE) -> Tirsdag | C34: 1.5 | F34: 45776 | G34: Tirsdag | H34: 2.5
A35: 45778 | B35: =VLOOKUP(formler!D36,formler!$A$2:$B$8,2,FALSE) -> Torsdag | C35: 0 | D35: 45413 | F35: 45778 | G35: Torsdag | H35: 0 | I35: 45413
A36: 45783 | B36: =VLOOKUP(formler!D37,formler!$A$2:$B$8,2,FALSE) -> Tirsdag | C36: 2.5 | F36: 45783 | G36: Tirsdag | H36: 1.5
A37: 45785 | B37: =VLOOKUP(formler!D38,formler!$A$2:$B$8,2,FALSE) -> Torsdag | C37: 1 | F37: 45785 | G37: Torsdag | H37: 1
A38: 45790 | B38: =VLOOKUP(formler!D39,formler!$A$2:$B$8,2,FALSE) -> Tirsdag | C38: 1.5 | F38: 45790 | G38: Tirsdag | H38: 1.5
A39: 45792 | B39: =VLOOKUP(formler!D40,formler!$A$2:$B$8,2,FALSE) -> Torsdag | C39: 1 | F39: 45792 | G39: Torsdag | H39: 1
A40: 45797 | B40: =VLOOKUP(formler!D41,formler!$A$2:$B$8,2,FALSE) -> Tirsdag | C40: 1.5 | F40: 45797 | G40: Tirsdag | H40: 2.5
A41: 45799 | B41: =VLOOKUP(formler!D42,formler!$A$2:$B$8,2,FALSE) -> Torsdag | C41: 1 | F41: 45799 | G41: Torsdag | H41: 1
A42: 45804 | B42: =VLOOKUP(formler!D43,formler!$A$2:$B$8,2,FALSE) -> Tirsdag | C42: 2.5 | F42: 45804 | G42: Tirsdag | H42: 1.5
A43: 45806 | B43: =VLOOKUP(formler!D44,formler!$A$2:$B$8,2,FALSE) -> Torsdag | C43: 0 | D43: Kr. Himmelfartsdag | F43: 45806 | G43: Torsdag | H43: 0 | I43: Kr. Himmelfartsdag
A44: 45811 | B44: =VLOOKUP(formler!D45,formler!$A$2:$B$8,2,FALSE) -> Tirsdag | C44: 1.5 | F44: 45811 | G44: Tirsdag | H44: 1.5
...
